Workbook

Sheet OIC input for DSR cal
A1: DSR & Stressed DSR - Basic information
A3: Borrower: | F3: Total gp exposure:
A4: Propose loan amount: | F4: Loan tenor:
A5: OIC: | F5: CA:
A6: Corp Type | B6: #1
A8: Where applicable, both cash flow forecast and debt-servicing ability should be conducted simultaneously when providing medium to long term facilities as below:-
A9: 1. Sydicated Loan, construction loan, term loan and mortgage loan with tenor > 1 year , including term loan under 內保外貸. For cashflow forecast, it should cover the whole period of loan life.
A11: Source of financial information:
A12: Historical DSR: | B12: Note | D12: Remarks:
A13: Type of statement: | B13: #2
A14: Latest Financial: | B14: #3 | D14: from: | F14: to:
A15: Full Year: | B15: #4
A16: Currency: | B16: #5
A18: Debt Financing: | C18: =C16 -> 0
A19: Existing Debt | B19: Note | C19: LN1 | D19: LN2 | E19: LN3 | F19: LN4 | G19: LN5 | H19: LN6 | I19: Sub-total | J19: Assumption & Justifications (please also marks your calculation):
A20: Existing LT Term Debt obligation | B20: #6 | I20: =SUM(C20:H20) -> 0
A21: Interest rate of Term Debt | B21: #7 | I21: =IF(I20=0,,(C20*C21+D20*D21+E20*E21+F20*F21+G20*G21+H20*H21)/I20) -> 0
A22: LT Term Loan principal repaid p.a. | B22: #6 | I22: =SUM(C22:H22) -> 0
A24: Bonds & Notes | B24: #8 | I24: =SUM(C24:H24) -> 0
A25: Interest Rate / Coupon rate | B25: #7 | I25: =IF(I24=0,,(C24*C25+D24*D25+E24*E25+F24*F25+G24*G25+H24*H25)/I24) -> 0
A26: Bonds & Notes maturing within 12 months | B26: #6 | I26: =SUM(C26:H26) -> 0
A28: ST / Revolving loan limit | B28: #6 | I28: =SUM(C28:H28) -> 0
A29: Interest rate of revolver | B29: #7 | I29: =IF(I28=0,,(C28*C29+D28*D29+E28*E29+F28*F29+G28*G29+H28*H29)/I28) -> 0
A32: New Debt
A33: Term Loan obligation | B33: #9 | I33: =SUM(C33:H33) -> 0
A34: Interest rate of Tern Loan | B34: #10 | I34: =IF(I33=0,,(C33*C34+D33*D34+E33*E34+F33*F34+G33*G34+H33*H34)/I33) -> 0
A35: Loan principal repaid p.a. | I35: =SUM(C35:H35) -> 0
A37: Bonds & Notes | B37: #9 | I37: =SUM(C37:H37) -> 0
A38: Interest Rate / Coupon rate | B38: #10 | I38: =IF(I37=0,,(C37*C38+D37*D38+E37*E38+F37*F38+G37*G38+H37*H38)/I37) -> 0
A40: ST / Revolving loan limit | B40: #9 | I40: =SUM(C40:H40) -> 0
A41: Interest rate of revolver | B41: #10 | I41: =IF(I40=0,,(C40*C41+D40*D41+E40*E41+F40*F41+G40*G41+H40*H41)/I40) -> 0
B44: Note | C44: Base case | D44: Stressed | E44: Assumption
A45: EBITDA | B45: #11 | D45: 0.1 | E45: discount on base EBITDA (ie 90% of base EBITDA)
A46: Add-on interest rate under stressed | B46: #12 | C46: NA | D46: 0.02
A48: #1: Input "0" for SME & Trading & "1" for Corporates & Manufacturing
A49: #2: Latest audited statement. Unaudited / draft statement are acceptable if the audited statements are not available.
A50: #3: Input latest financial year end ie 31 Dec 2022 & input financial period starts and end dates under remarks
A51: #4: Input "Y" for full year statement, otherwise, "N". For financial period covered not equal to 12 months, P&L for Latest AFS in the "OIC input for cash flow forecast" worksheet have to be adjusted manually to reflect annualised figures.
A52: #5: Currency should be the reported currency as per audited statements
A53: #6: OIC should try to obtain facilities letter or declaration from borrower on total GBF, interest rate & repayment schedule with other lenders. If information is available. input standalone LN obligation one by one or otherwise, aggregated loan obligation from latest audited F/S. All outstanding term debt (> than 1 year) and bonds including current portion long term debt and bonds, shall be input into respective item under “Existing Debt” section. Current portion long term debt disclosed in the financial statement or long term debt to be repaid within 12 months as per loan repayment schedule shall be input into “Term Loan Principal Repaid p.a.” and “Bonds & Notes maturing within 12 months” respectively. If there has been refinancing arrangement, revised repayment could only be input herewith with completed refinancing activities during the current financial year. Short term debt shall be input under ST Revolving loan section. Given the nature of revolving loan, one can assume all short term debt to be roll-over unless OIC has knowledge of banks exiting the banking relationship with the Borrower / Group. For mortgage installment loan, assumed principal repayment shall be after deduction of interest payment ie monthly installment x 12 mths - interest (current loan o/s x interest rate)
...

Sheet OIC input for cashflow
A1: OIC input basic information for cashflow forecast
A3: ='OIC input for DSR cal'!A3 -> Borrower: | C3: ='OIC input for DSR cal'!C3 -> 0 | G3: Period:
A4: ='OIC input for DSR cal'!A4 -> Propose loan amount: | C4: ='OIC input for DSR cal'!C4 -> 0 | G4: ='OIC input for DSR cal'!F3 -> Total gp exposure: | I4: ='OIC input for DSR cal'!H3 -> 0
A6: Basic Information:
A7: ='OIC input for DSR cal'!C16 -> 0 | D7: Note | E7: Latest AFS | F7: Yr 1 | G7: Yr. 2 | H7: Yr 3 | I7: Yr. 4 | J7: Yr. 5 | K7: Yr. 6 | L7: Yr. 7 | M7: Yr. 8 | N7: Yr. 9 | O7: Yr. 10 | P7: Yr. 11 | Q7: Yr. 12 | R7: Stressed | S7: Assumption
A8: FYE | E8: =+'OIC input for DSR cal'!C14 -> 0
A9: Sales & growth rate (%) in coming years | D9: #1 | R9: 0.1
A10: Current & forecast Gross Profit Margin ("GPM" in %) in coming years | D10: #2 | R10: 0
A11: Current & forecast Depreciation/Amortization charged to COGS (absolute amount) | D11: #3 | R11: NA
A12: Operating expenses in absolute amount (excluding depreciation & amortization) & growth rate (%) in coming years | D12: #4 | R12: NA
A13: Current & forecast Depreciation / Amortization (excluding charged in COGS) absolute amt in coming years | D13: #5 | R13: NA
A14: Investment/rental income & its absolute amt in coming years | D14: #6 | R14: NA
A15: of which non-cash investment income | D15: #6
A16: Share of contributions from associates or JV (P/L items) & its absolute amount in coming years | D16: #7 | R16: NA
A17: Dividend received from Associates or JV (absolute amt, from CF statement) & its absolute amt in the coming years | D17: #8
A18: Dividend receivable (B/S item) & its absolute amount in coming years | D18: #9 | R18: NA
A19: All other non-operating income & growth rate in coming years | D19: #10 | R19: NA
A20: All other non-operating expenditure & growth rate in coming years | D20: #11 | R20: NA
A21: Current & forecast Tax expense rate (% of pre-tax NP) in coming years | D21: #12 | R21: NA
A22: Current & forecast Dividends payout rate (% of NP) in coming years | D22: #13 | R22: NA
A23: Current & forecast Dividends payable (B/S item) absolute amt in coming years | D23: #14 | R23: NA
A24: Current & forecast Bad debt provision / exp (% of sales) in coming years | D24: #15 | R24: NA
A25: Debtors' t/o (days) | D25: #16 | R25: NA
A26: Debtors (absolute amt) | D26: #17 | F26: NA | G26: NA | H26: NA | I26: NA | J26: NA | K26: NA | L26: NA | M26: NA | N26: NA | O26: NA | P26: NA | Q26: NA | R26: NA
A27: Inventory t/o (days) | D27: #18 | R27: NA
A28: Inventory (absolute amt) | D28: #19 | F28: NA | G28: NA | H28: NA | I28: NA | J28: NA | K28: NA | L28: NA | M28: NA | N28: NA | O28: NA | P28: NA | Q28: NA | R28: NA
A29: Creditors' t/o (days) | D29: #20 | R29: NA
A30: Creditor (absolute amt) | D30: #21 | F30: NA | G30: NA | H30: NA | I30: NA | J30: NA | K30: NA | L30: NA | M30: NA | N30: NA | O30: NA | P30: NA | Q30: NA | R30: NA
A31: CAPEX (absolute amt) | D31: #22 | E31: NA | R31: 0
A32: Capex Financing Ratio | D32: #22 | R32: NA
A33: Estimated useful life of CAPEX (number of years) | D33: #23 | E33: NA | R33: NA
A34: Additional Depreciation for CAPEX (for Corp) | E34: NA | F34: =IF(OR('OIC input for DSR cal'!C6=0,F31=0,F33=0),0,F31/F33) -> 0 | G34: =IF(OR('OIC input for DSR cal'!C6=0,G31=0,G33=0),0,G31/G33) -> 0 | H34: =IF(OR('OIC input for DSR cal'!C6=0,H31=0,H33=0),0,H31/H33) -> 0 | I34: =IF(OR('OIC input for DSR cal'!C6=0,I31=0,I33=0),0,I31/I33) -> 0 | J34: =IF(OR('OIC input for DSR cal'!C6=0,J31=0,J33=0),0,J31/J33) -> 0 | K34: =IF(OR('OIC input for DSR cal'!C6=0,K31=0,K33=0),0,K31/K33) -> 0 | L34: =IF(OR('OIC input for DSR cal'!C6=0,L31=0,L33=0),0,L31/L33) -> 0 | M34: =IF(OR('OIC input for DSR cal'!C6=0,M31=0,M33=0),0,M31/M33) -> 0 | N34: =IF(OR('OIC input for DSR cal'!C6=0,N31=0,N33=0),0,N31/N33) -> 0 | O34: =IF(OR('OIC input for DSR cal'!C6=0,O31=0,O33=0),0,O31/O33) -> 0 | P34: =IF(OR('OIC input for DSR cal'!C6=0,P31=0,P33=0),0,P31/P33) -> 0 | Q34: =IF(OR('OIC input for DSR cal'!C6=0,Q31=0,Q33=0),0,Q31/Q33) -> 0 | R34: NA
A35: Additional Depreciation for CAPEX (for Corp - stressed) | E35: NA | F35: =IF(OR('OIC input for DSR cal'!$C$6=0,F31=0,F33=0),0,F31*(1-$R$31)/F33) -> 0 | G35: =IF(OR('OIC input for DSR cal'!$C$6=0,G31=0,G33=0),0,G31*(1-$R$31)/G33) -> 0 | H35: =IF(OR('OIC input for DSR cal'!$C$6=0,H31=0,H33=0),0,H31*(1-$R$31)/H33) -> 0 | I35: =IF(OR('OIC input for DSR cal'!$C$6=0,I31=0,I33=0),0,I31*(1-$R$31)/I33) -> 0 | J35: =IF(OR('OIC input for DSR cal'!$C$6=0,J31=0,J33=0),0,J31*(1-$R$31)/J33) -> 0 | K35: =IF(OR('OIC input for DSR cal'!$C$6=0,K31=0,K33=0),0,K31*(1-$R$31)/K33) -> 0 | L35: =IF(OR('OIC input for DSR cal'!$C$6=0,L31=0,L33=0),0,L31*(1-$R$31)/L33) -> 0 | M35: =IF(OR('OIC input for DSR cal'!$C$6=0,M31=0,M33=0),0,M31*(1-$R$31)/M33) -> 0 | ... Q35: =IF(OR('OIC input for DSR cal'!$C$6=0,Q31=0,Q33=0),0,Q31*(1-$R$31)/Q33) -> 0 | R35: NA
A36: Additional Depreciation for CAPEX (for SME / trading) | E36: NA | F36: =IF(OR('OIC input for DSR cal'!C6=1,F31=0,F33=0),0,F31/F33) -> 0 | G36: =IF(OR('OIC input for DSR cal'!C6=1,G31=0,G33=0),0,G31/G33) -> 0 | H36: =IF(OR('OIC input for DSR cal'!C6=1,H31=0,H33=0),0,H31/H33) -> 0 | I36: =IF(OR('OIC input for DSR cal'!C6=1,I31=0,I33=0),0,I31/I33) -> 0 | J36: =IF(OR('OIC input for DSR cal'!C6=1,J31=0,J33=0),0,J31/J33) -> 0 | K36: =IF(OR('OIC input for DSR cal'!C6=1,K31=0,K33=0),0,K31/K33) -> 0 | L36: =IF(OR('OIC input for DSR cal'!C6=1,L31=0,L33=0),0,L31/L33) -> 0 | M36: =IF(OR('OIC input for DSR cal'!C6=1,M31=0,M33=0),0,M31/M33) -> 0 | N36: =IF(OR('OIC input for DSR cal'!C6=1,N31=0,N33=0),0,N31/N33) -> 0 | O36: =IF(OR('OIC input for DSR cal'!C6=1,O31=0,O33=0),0,O31/O33) -> 0 | P36: =IF(OR('OIC input for DSR cal'!C6=1,P31=0,P33=0),0,P31/P33) -> 0 | Q36: =IF(OR('OIC input for DSR cal'!C6=1,Q31=0,Q33=0),0,Q31/Q33) -> 0 | R36: NA
A37: Additional Depreciation for CAPEX (for SME / trading - stressed) | E37: NA | F37: =IF(OR('OIC input for DSR cal'!$C$6=1,F31=0,F33=0),0,F31*(1-$R$31)/F33) -> 0 | G37: =IF(OR('OIC input for DSR cal'!$C$6=1,G31=0,G33=0),0,G31*(1-$R$31)/G33) -> 0 | H37: =IF(OR('OIC input for DSR cal'!$C$6=1,H31=0,H33=0),0,H31*(1-$R$31)/H33) -> 0 | I37: =IF(OR('OIC input for DSR cal'!$C$6=1,I31=0,I33=0),0,I31*(1-$R$31)/I33) -> 0 | J37: =IF(OR('OIC input for DSR cal'!$C$6=1,J31=0,J33=0),0,J31*(1-$R$31)/J33) -> 0 | K37: =IF(OR('OIC input for DSR cal'!$C$6=1,K31=0,K33=0),0,K31*(1-$R$31)/K33) -> 0 | L37: =IF(OR('OIC input for DSR cal'!$C$6=1,L31=0,L33=0),0,L31*(1-$R$31)/L33) -> 0 | M37: =IF(OR('OIC input for DSR cal'!$C$6=1,M31=0,M33=0),0,M31*(1-$R$31)/M33) -> 0 | ... Q37: =IF(OR('OIC input for DSR cal'!$C$6=1,Q31=0,Q33=0),0,Q31*(1-$R$31)/Q33) -> 0 | R37: NA
A38: Acquisition of investment (absolute amt, fm CF statement) | D38: #24 | R38: 0
A39: Proceeds of disposal of FA/investment (absolute amt, fm CF statement)) | D39: #25 | R39: NA
A40: all other current assets (absolute amt) in coming years | D40: #26 | R40: NA
A41: all other current liabilities (absolute amt) in coming years | D41: #27 | R41: NA
A42: interco claim (absolute amt) | D42: #28 | R42: NA
...
